<!DOCTYPE html>
<html lang="en">
  <head>
    <meta charset="UTF-8" />
    <meta name="viewport" content="width=device-width, initial-scale=1.0" />
    <title>프로미스 에러 처리</title>
  </head>

  <body>
    <script>
      const promiseGet = (url) => {
        return new Promise((resolve, reject) => {
          const xhr = new XMLHttpRequest();

          xhr.open("GET", url);
          xhr.send();

          xhr.onload = () => {
            if (xhr.status === 200) {
              resolve(JSON.parse(xhr.response));
            } else {
              reject(new Error(xhr.status));
            }
          };
        });
      };

      const wrongUrl = "https://jsonplaceholder.typicode.com/XXX/1";

      // 아래의 두 코드는 동일하게 동작한다.
      // 비동기 처리에서 발생한 에러는 후속 처리 메서드 then의 두 번째 콜백함수 또는 catch의 콜백함수를 통하여 처리 가능하다.)
      promiseGet(wrongUrl).then(
        (res) => console.log(res),
        (e) => console.error(e)
      );
      // Error: 404

      promiseGet(wrongUrl)
        .then((res) => console.log(res))
        .catch((e) => console.error(e));
      // Error: 404

      // 후속 처리 메서드 then의 두 번째 콜백함수와 catch의 콜백함수의 차이점
      // then 메서드의 두 번째 콜백함수는 첫 번째 콜백함수에서 발생한 에러를 캐치하지 못하고 코드가 복잡해져서 가독성이 좋지 않다.
      // catch 메서드는 모든 then 메서드를 호출한 이후에 호출하면 비동기 처리에서 발생한 에러 뿐만 아니라 then 메서드 내부에서 발생한 에러까지 모두 캐치할 수 있다.
      // 에러 처리는 then 메서드가 아닌 catch 메서드에서 진행할 것을 권장한다.

      promiseGet("https://jsonplaceholder.typicode.com/todos/1").then(
        (res) => console.xxx(res),
        (e) => console.error(e)
      );
      // 두 번째 콜백함수는 첫 번째 콜백함수에서 발생한 에러를 캐치하지 못한다.

      promiseGet("https://jsonplaceholder.typicode.com/todos/1")
        .then((res) => console.xxx(res))
        .catch((e) => console.error(e));
      // promiseError.html:55 TypeError: console.xxx is not a function
    </script>
  </body>
</html>
